Workbook

Sheet RAW_Data
A1: Tender_ID | B1: Submission_Date | C1: Client_Industry | D1: Client_Region | E1: Equipment_Category | F1: Equipment_Type | G1: Project_Type | H1: Tender_Value_IDR | I1: Our_Bid_IDR | J1: Bid_Margin_Pct | K1: Lead_Time_Days | L1: Status | M1: Is_Win | N1: Is_Loss | O1: Win_Loss_Reason | P1: Competitor_Type | Q1: Principal_Origin | R1: Quotation_Revisions | S1: Decision_Maker_Level | T1: Tender_Quarter
A2: TND-2022-001 | B2: 44576 | C2: Sugar | D2: Lampung | E2: Process Machinery | F2: Centrifugal Machine | G2: New Installation | H2: 2850000000 | I2: 2750000000 | J2: 12.5 | K2: 90 | L2: Win | M2: =IF(tblTender[[#This Row],[Status]]="Win",1,0) -> 1 | N2: =IF(tblTender[[#This Row],[Status]]="Loss",1,0) -> 0 | O2: Better Technical Specs | P2: Local Distributor | Q2: European | R2: 2 | S2: Plant Manager | T2: Q1-2022
A3: TND-2022-002 | B3: 44589 | C3: Pulp & Paper | D3: Riau | E3: Power & Utilities | F3: Generator 2MW | G3: Replacement | H3: 4200000000 | I3: 4150000000 | J3: 11.2 | K3: 120 | L3: Loss | M3: =IF(tblTender[[#This Row],[Status]]="Win",1,0) -> 0 | N3: =IF(tblTender[[#This Row],[Status]]="Loss",1,0) -> 1 | O3: Higher Price | P3: International OEM | Q3: European | R3: 1 | S3: Procurement Director | T3: Q1-2022
A4: TND-2022-003 | B4: 44602 | C4: Sugar | D4: East Java | E4: Power & Utilities | F4: Transformer 1500kVA | G4: New Installation | H4: 1850000000 | I4: 1780000000 | J4: 15.8 | K4: 75 | L4: Win | M4: =IF(tblTender[[#This Row],[Status]]="Win",1,0) -> 1 | N4: =IF(tblTender[[#This Row],[Status]]="Loss",1,0) -> 0 | O4: Established Relationship | P4: Local Distributor | Q4: Asian | R4: 1 | S4: Engineering Head | T4: Q1-2022
A5: TND-2022-004 | B5: 44614 | C5: Power Generation | D5: South Sumatra | E5: Instrumentation | F5: Pressure Sensors Set | G5: Replacement | H5: 425000000 | I5: 418000000 | J5: 18.3 | K5: 45 | L5: Win | M5: =IF(tblTender[[#This Row],[Status]]="Win",1,0) -> 1 | N5: =IF(tblTender[[#This Row],[Status]]="Loss",1,0) -> 0 | O5: Faster Lead Time | P5: Local Distributor | Q5: European | R5: 2 | S5: Procurement Manager | T5: Q1-2022
A6: TND-2022-005 | B6: 44625 | C6: Sugar | D6: Central Java | E6: Material Handling | F6: Conveyor System | G6: Upgrade | H6: 1250000000 | I6: 1295000000 | J6: 14.5 | K6: 60 | L6: Loss | M6: =IF(tblTender[[#This Row],[Status]]="Win",1,0) -> 0 | N6: =IF(tblTender[[#This Row],[Status]]="Loss",1,0) -> 1 | O6: Technical Mismatch | P6: International OEM | Q6: European | R6: 3 | S6: Plant Manager | T6: Q1-2022
A7: TND-2022-006 | B7: 44638 | C7: Pulp & Paper | D7: East Kalimantan | E7: Power & Utilities | F7: Electromotor 250HP | G7: Replacement | H7: 680000000 | I7: 665000000 | J7: 13.2 | K7: 50 | L7: Win | M7: =IF(tblTender[[#This Row],[Status]]="Win",1,0) -> 1 | N7: =IF(tblTender[[#This Row],[Status]]="Loss",1,0) -> 0 | O7: Better Technical Specs | P7: Local Distributor | Q7: European | R7: 1 | S7: Engineering Head | T7: Q1-2022
A8: TND-2022-007 | B8: 44653 | C8: Sugar | D8: Lampung | E8: Process Machinery | F8: Centrifugal Machine | G8: New Installation | H8: 3100000000 | I8: 3050000000 | J8: 11.8 | K8: 95 | L8: Loss | M8: =IF(tblTender[[#This Row],[Status]]="Win",1,0) -> 0 | N8: =IF(tblTender[[#This Row],[Status]]="Loss",1,0) -> 1 | O8: Higher Price | P8: International OEM | Q8: European | R8: 2 | S8: Plant Manager | T8: Q2-2022
A9: TND-2022-008 | B9: 44666 | C9: Power Generation | D9: Jakarta | E9: Power & Utilities | F9: Generator 5MW | G9: New Installation | H9: 8500000000 | I9: 8350000000 | J9: 9.5 | K9: 150 | L9: Loss | M9: =IF(tblTender[[#This Row],[Status]]="Win",1,0) -> 0 | N9: =IF(tblTender[[#This Row],[Status]]="Loss",1,0) -> 1 | O9: Higher Price | P9: International OEM | Q9: European | R9: 3 | S9: Procurement Director | T9: Q2-2022
A10: TND-2022-009 | B10: 44679 | C10: Sugar | D10: East Java | E10: Instrumentation | F10: Control System Upgrade | G10: Upgrade | H10: 950000000 | I10: 925000000 | J10: 17.2 | K10: 55 | L10: Win | M10: =IF(tblTender[[#This Row],[Status]]="Win",1,0) -> 1 | N10: =IF(tblTender[[#This Row],[Status]]="Loss",1,0) -> 0 | O10: Better Technical Specs | P10: Local Distributor | Q10: Asian | R10: 1 | S10: Engineering Head | T10: Q2-2022
A11: TND-2022-010 | B11: 44693 | C11: Pulp & Paper | D11: Riau | E11: Material Handling | F11: Pump Set Industrial | G11: Replacement | H11: 520000000 | I11: 498000000 | J11: 15.5 | K11: 40 | L11: Win | M11: =IF(tblTender[[#This Row],[Status]]="Win",1,0) -> 1 | N11: =IF(tblTender[[#This Row],[Status]]="Loss",1,0) -> 0 | O11: Faster Lead Time | P11: Local Distributor | Q11: European | R11: 1 | S11: Procurement Manager | T11: Q2-2022
A12: TND-2022-011 | B12: 44706 | C12: Sugar | D12: South Sumatra | E12: Power & Utilities | F12: Inverter VSD 200HP | G12: Replacement | H12: 385000000 | I12: 395000000 | J12: 16.8 | K12: 35 | L12: Loss | M12: =IF(tblTender[[#This Row],[Status]]="Win",1,0) -> 0 | N12: =IF(tblTender[[#This Row],[Status]]="Loss",1,0) -> 1 | O12: Higher Price | P12: Local Distributor | Q12: Asian | R12: 2 | S12: Engineering Head | T12: Q2-2022
A13: TND-2022-012 | B13: 44720 | C13: Power Generation | D13: West Java | E13: Process Machinery | F13: Gearbox Heavy Duty | G13: Replacement | H13: 720000000 | I13: 705000000 | J13: 14 | K13: 70 | L13: Win | M13: =IF(tblTender[[#This Row],[Status]]="Win",1,0) -> 1 | N13: =IF(tblTender[[#This Row],[Status]]="Loss",1,0) -> 0 | O13: Established Relationship | P13: Local Distributor | Q13: European | R13: 1 | S13: Plant Manager | T13: Q2-2022
... A105: TND-2025-104 | B105: 46008 | C105: Sugar | D105: South Sumatra | E105: Process Machinery | F105: Centrifugal Machine | G105: Replacement | H105: 2650000000 | I105: 2585000000 | J105: 12.5 | K105: 95 | L105: Win | M105: =IF(tblTender[[#This Row],[Status]]="Win",1,0) -> 1 | N105: =IF(tblTender[[#This Row],[Status]]="Loss",1,0) -> 0 | O105: Better Technical Specs | P105: Local Distributor | Q105: European | R105: 1 | S105: Plant Manager | T105: Q4-2025

Sheet Calculation
A2: Total Tender | B2: =COUNTA(tblTender[Tender_ID]) -> 104
A3: Total Win | B3: =COUNTIF(tblTender[Status],"Win") -> 72
A4: Total Losses | B4: =COUNTIF(tblTender[Status],"Loss") -> 32
A5: Win Rate (%) | B5: =COUNTIF(tblTender[Status],"Win")/COUNTA(tblTender[Tender_ID]) -> 0.69230769
A6: Total Tender Value | B6: =SUM(tblTender[Tender_Value_IDR]) -> 167465000000
A7: Won Value | B7: =SUMIF(tblTender[Status],"Win",tblTender[Tender_Value_IDR]) -> 105275000000
A8: Lost Value | B8: =SUMIF(tblTender[Status],"Loss",tblTender[Tender_Value_IDR]) -> 62190000000
A9: Avg Win Margin (%) | B9: =AVERAGEIF(tblTender[Status],"Win",tblTender[Bid_Margin_Pct])/100 -> 0.15438889
A10: Avg Loss Margin (%) | B10: =AVERAGEIF(tblTender[Status],"Loss",tblTender[Bid_Margin_Pct])/100 -> 0.13990625
A11: Avg Win Deal Size | B11: =AVERAGEIF(tblTender[Status],"Win",tblTender[Tender_Value_IDR]) -> 1.4621528e+09
A12: Win Value Conversion | B12: =SUMIF(tblTender[Status],"Win",tblTender[Tender_Value_IDR])/SUM(tblTender[Tender_Value_IDR]) -> 0.62863882
A15: Quarterly Trend Analysis
A17: METRIC | B17: VALUE
A18: WIN RATE TREND :
A19: Avg Win Rate 2022 | B19: =COUNTIFS(tblTender[Tender_Quarter],"Q1-2022",tblTender[Status],"Win")/COUNTIF(tblTender[Tender_Quarter],"Q1-2022")*0.25+COUNTIFS(tblTender[Tender_Quarter],"Q2-2022",tblTender[Status],"Win")/COUNTIF(tblTender[Tender_Quarter],"Q2-2022")*0.25+COUNTIFS(tblTender[Tender_Quarter],"Q3-2022",tblTender[Status],"Win")/COUNTIF(tblTender[Tender_Quarter],"Q3-2022")*0.25+COUNTIFS(tblTender[Tender_Quarter],"Q4-2022",tblTender[Status],"Win")/COUNTIF(tblTender[Tender_Quarter],"Q4-2022")*0.25 -> 0.63095238
A20: Avg Win Rate 2025 | B20: =COUNTIFS(tblTender[Tender_Quarter],"Q1-2025",tblTender[Status],"Win")/COUNTIF(tblTender[Tender_Quarter],"Q1-2025")*0.25+COUNTIFS(tblTender[Tender_Quarter],"Q2-2025",tblTender[Status],"Win")/COUNTIF(tblTender[Tender_Quarter],"Q2-2025")*0.25+COUNTIFS(tblTender[Tender_Quarter],"Q3-2025",tblTender[Status],"Win")/COUNTIF(tblTender[Tender_Quarter],"Q3-2025")*0.25+COUNTIFS(tblTender[Tender_Quarter],"Q4-2025",tblTender[Status],"Win")/COUNTIF(tblTender[Tender_Quarter],"Q4-2025")*0.25 -> 0.76190476
A21: Trend Change | B21: =B20-B19 -> 0.13095238
A22: Verditct | B22: {=_xlfn.IFS(B2>0,"Improving",B21=0,"Flat",TRUE,"Declining")} -> Improving
A24: SEASONALITY :
A25: Best Quarter | B25: =INDEX(Pivot_Analyses!$G$113:$G$128,MATCH(MAX(Pivot_Analyses!$I$113:$I$128),Pivot_Analyses!$I$113:$I$128,0)) -> Q3-2023
A26: Best Win Rate | B26: =MAX(Pivot_Analyses!I113:I128) -> 0.85714286
A27: Worst Quarter | B27: =INDEX(Pivot_Analyses!$G$113:$G$128,MATCH(MIN(Pivot_Analyses!$I$113:$I$128),Pivot_Analyses!$I$113:$I$128,0)) -> Q2-2022
A28: Worst Win Rate | B28: =MIN(Pivot_Analyses!I113:I128) -> 0.57142857
A29: Pattern | B29: Q3 - 2023 Peak
A31: Q3 Pattren Check
A32: Q3-2022 WR | B32: =COUNTIFS(tblTender[Tender_Quarter],"Q3-2022",tblTender[Status],"Win")/COUNTIF(tblTender[Tender_Quarter],"Q3-2022") -> 0.57142857
A33: Q3-2023 WR | B33: =COUNTIFS(tblTender[Tender_Quarter],"Q3-2023",tblTender[Status],"Win")/COUNTIF(tblTender[Tender_Quarter],"Q3-2023") -> 0.85714286
A34: Q3-2024 WR | B34: =COUNTIFS(tblTender[Tender_Quarter],"Q3-2024",tblTender[Status],"Win")/COUNTIF(tblTender[Tender_Quarter],"Q3-2024") -> 0.66666667
A35: Q3-2025 WR | B35: =COUNTIFS(tblTender[Tender_Quarter],"Q3-2025",tblTender[Status],"Win")/COUNTIF(tblTender[Tender_Quarter],"Q3-2025") -> 0.71428571
A36: Averang Q3 | B36: =AVERAGE(B32:B35) -> 0.70238095
A38: VOLUME :
A39: Total Tender 2022 | B39: =COUNTIF(tblTender[Tender_Quarter],"*2022") -> 27
A40: Total Tender 2025 | B40: =COUNTIF(tblTender[Tender_Quarter],"*2025") -> 25
A41: Change | B41: =B40-B39 -> -2
A42: Verditct | B42: {=_xlfn.IFS(B14>0,"Improving",B41=0,"Flat",TRUE,"Strategic Selectivity")} -> Strategic Selectivity

Sheet Pivot_Analyses
A1: Total Tender | B1: Column Labels
A2: Industry | B2: Loss | C2: Win | D2: Grand Total | E2: Win Rate | G2: Industry | H2: Win Rate
A3: Power Generation | B3: 6 | C3: 18 | D3: 24 | E3: =COUNTIFS(tblTender[Client_Industry],"Power Generation",tblTender[Status],"Win")/COUNTIF(tblTender[Client_Industry],"Power Generation") -> 0.75 | G3: Pulp & Paper | H3: =E4 -> 0.54166667
A4: Pulp & Paper | B4: 11 | C4: 13 | D4: 24 | E4: =COUNTIFS(tblTender[Client_Industry],"Pulp & Paper",tblTender[Status],"Win")/COUNTIF(tblTender[Client_Industry],"Pulp & Paper") -> 0.54166667 | G4: Sugar | H4: =E5 -> 0.73214286
A5: Sugar | B5: 15 | C5: 41 | D5: 56 | E5: =COUNTIFS(tblTender[Client_Industry],"Sugar",tblTender[Status],"Win")/COUNTIF(tblTender[Client_Industry],"Sugar") -> 0.73214286 | G5: Power Generation | H5: =E3 -> 0.75
A6: Grand Total | B6: 32 | C6: 72 | D6: 104
B25: Column Labels
B26: Count of Tender | D26: Sum of Tender_Value | F26: Total Count of Tender | G26: Total Sum of Tender_Value
A27: Row Labels | B27: Loss | C27: Win | D27: Loss | E27: Win | I27: Win Rate | J27: Avg Value (Mio) | K27: Total Count | L27: Category Rating | N27: Category | O27: Avg. Value (Mio) | P27: Win Rate % | Q27: Total Count
A28: Instrumentation | B28: 5 | C28: 11 | D28: 5125000000 | E28: 8750000000 | F28: 16 | G28: 13875000000 | I28: =COUNTIFS(tblTender[Equipment_Category],"Instrumentation",tblTender[Status],"Win")/COUNTIF(tblTender[Equipment_Category],"Instrumentation") -> 0.6875 | J28: =AVERAGEIF(tblTender[Equipment_Category],"Instrumentation",tblTender[Tender_Value_IDR])/1000000 -> 867.1875 | K28: =COUNTIF(tblTender[Equipment_Category],"Instrumentation") -> 16 | L28: =IF(AND(I28>=0.7,J28>=1000),"⭐ STAR",IF(I28>=0.8,"⚡ QUICK WIN",IF(J28>=1500,"💰 BIG DEAL","STEADY"))) -> STEADY | N28: Instrumentation | O28: =J28 -> 867.1875 | P28: =I28 -> 0.6875 | Q28: =K28 -> 16
A29: Material Handling | B29: 9 | C29: 7 | D29: 10610000000 | E29: 4980000000 | F29: 16 | G29: 15590000000 | I29: =COUNTIFS(tblTender[Equipment_Category],"Material Handling",tblTender[Status],"Win")/COUNTIF(tblTender[Equipment_Category],"Material Handling") -> 0.4375 | J29: =AVERAGEIF(tblTender[Equipment_Category],"Material Handling",tblTender[Tender_Value_IDR])/1000000 -> 974.375 | K29: =COUNTIF(tblTender[Equipment_Category],"Material Handling") -> 16 | L29: =IF(AND(I29>=0.7,J29>=1000),"⭐ STAR",IF(I29>=0.8,"⚡ QUICK WIN",IF(J29>=1500,"💰 BIG DEAL","STEADY"))) -> STEADY | N29: =A29 -> Material Handling | O29: =J29 -> 974.375 | P29: =I29 -> 0.4375 | Q29: =K29 -> 16
A30: Power & Utilities | B30: 12 | C30: 20 | D30: 32995000000 | E30: 51990000000 | F30: 32 | G30: 84985000000 | I30: =COUNTIFS(tblTender[Equipment_Category],"Power & Utilities",tblTender[Status],"Win")/COUNTIF(tblTender[Equipment_Category],"Power & Utilities") -> 0.625 | J30: =AVERAGEIF(tblTender[Equipment_Category],"Power & Utilities",tblTender[Tender_Value_IDR])/1000000 -> 2655.7812 | K30: =COUNTIF(tblTender[Equipment_Category],"Power & Utilities") -> 32 | L30: =IF(AND(I30>=0.7,J30>=1000),"⭐ STAR",IF(I30>=0.8,"⚡ QUICK WIN",IF(J30>=1500,"💰 BIG DEAL","STEADY"))) -> 💰 BIG DEAL | N30: =A30 -> Power & Utilities | O30: =J30 -> 2655.7812 | P30: =I30 -> 0.625 | Q30: =K30 -> 32
A31: Process Machinery | B31: 6 | C31: 24 | D31: 13460000000 | E31: 36810000000 | F31: 30 | G31: 50270000000 | I31: =COUNTIFS(tblTender[Equipment_Category],"Process Machinery",tblTender[Status],"Win")/COUNTIF(tblTender[Equipment_Category],"Process Machinery") -> 0.8 | J31: =AVERAGEIF(tblTender[Equipment_Category],"Process Machinery",tblTender[Tender_Value_IDR])/1000000 -> 1675.6667 | K31: =COUNTIF(tblTender[Equipment_Category],"Process Machinery") -> 30 | L31: =IF(AND(I31>=0.7,J31>=1000),"⭐ STAR",IF(I31>=0.8,"⚡ QUICK WIN",IF(J31>=1500,"💰 BIG DEAL","STEADY"))) -> ⭐ STAR | N31: =A31 -> Process Machinery | O31: =J31 -> 1675.6667 | P31: =I31 -> 0.8 | Q31: =K31 -> 30
A32: Spare Parts | C32: 10 | E32: 2745000000 | F32: 10 | G32: 2745000000 | I32: =COUNTIFS(tblTender[Equipment_Category],"Spare Parts",tblTender[Status],"Win")/COUNTIF(tblTender[Equipment_Category],"Spare Parts") -> 1 | J32: =AVERAGEIF(tblTender[Equipment_Category],"Spare Parts",tblTender[Tender_Value_IDR])/1000000 -> 274.5 | K32: =COUNTIF(tblTender[Equipment_Category],"Spare Parts") -> 10 | L32: =IF(AND(I32>=0.7,J32>=1000),"⭐ STAR",IF(I32>=0.8,"⚡ QUICK WIN",IF(J32>=1500,"💰 BIG DEAL","STEADY"))) -> ⚡ QUICK WIN | N32: =A32 -> Spare Parts | O32: =J32 -> 274.5 | P32: =I32 -> 1 | Q32: =K32 -> 10
A33: Grand Total | B33: 32 | C33: 72 | D33: 62190000000 | E33: 105275000000 | F33: 104 | G33: 167465000000
A59: Status | B59: Loss
A61: Reason | B61: Total Tender | D61: % of Total Loss | E61: Total value Lost (Mio) | G61: Lost Reason | H61: Count
A62: Higher Price | B62: 25 | D62: =COUNTIFS(tblTender[Win_Loss_Reason],"Higher Price",tblTender[Status],"Loss")/COUNTIF(tblTender[Status],"Loss") -> 0.78125 | E62: =SUMIFS(tblTender[Tender_Value_IDR],tblTender[Win_Loss_Reason],"Higher Price",tblTender[Status],"Loss")/1000000 -> 49810 | G62: =A62 -> Higher Price | H62: =GETPIVOTDATA("Tender_ID",$A$61,"Win_Loss_Reason","Higher Price") -> 25
A63: Lost to Tender Specs | B63: 6 | D63: =COUNTIFS(tblTender[Win_Loss_Reason],"Lost to Tender Specs",tblTender[Status],"Loss")/COUNTIF(tblTender[Status],"Loss") -> 0.1875 | E63: =SUMIFS(tblTender[Tender_Value_IDR],tblTender[Win_Loss_Reason],"Lost to Tender Specs",tblTender[Status],"Loss")/1000000 -> 11130 | G63: =A63 -> Lost to Tender Specs | H63: =GETPIVOTDATA("Tender_ID",$A$61,"Win_Loss_Reason","Lost to Tender Specs") -> 6
A64: Technical Mismatch | B64: 1 | D64: =COUNTIFS(tblTender[Win_Loss_Reason],"Technical Mismatch",tblTender[Status],"Loss")/COUNTIF(tblTender[Status],"Loss") -> 0.03125 | E64: =SUMIFS(tblTender[Tender_Value_IDR],tblTender[Win_Loss_Reason],"Technical Mismatch",tblTender[Status],"Loss")/1000000 -> 1250 | G64: =A64 -> Technical Mismatch | H64: =GETPIVOTDATA("Tender_ID",$A$61,"Win_Loss_Reason","Technical Mismatch") -> 1
A65: Grand Total | B65: 32 | D65: =COUNTIFS(tblTender[Win_Loss_Reason],"Established Relationship",tblTender[Status],"Loss")/COUNTIF(tblTender[Status],"Loss") -> 0 | E65: =SUMIFS(tblTender[Tender_Value_IDR],tblTender[Win_Loss_Reason],"Established Relationship",tblTender[Status],"Loss")/1000000 -> 0 | H65: =SUM(H62:H64) -> 32
A82: Status | B82: Loss
A84: Count of Tender_ID | B84: Column Labels
A85: Industry | B85: Higher Price | C85: Lost to Tender Specs | D85: Technical Mismatch | E85: Total Loss
A86: Power Generation | B86: 6 | E86: 6
A87: Pulp & Paper | B87: 10 | C87: 1 | E87: 11
A88: Sugar | B88: 9 | C88: 5 | D88: 1 | E88: 15
A89: Total Loss | B89: 25 | C89: 6 | D89: 1 | E89: 32
A92: Equipment_Category | B92: Material Handling
A93: Status | B93: Loss
A95: Category | B95: Total Loss | C95: Tender Value
A96: Higher Price | B96: 5 | C96: 5620000000
A97: Piping System | B97: 1 | C97: 1080000000
A98: Piping System Industrial | B98: 2 | C98: 2700000000
A99: Pump Industrial | B99: 1 | C99: 950000000
A100: Pump Industrial Heavy Duty | B100: 1 | C100: 890000000
A101: Lost to Tender Specs | B101: 3 | C101: 3740000000
A102: Conveyor System | B102: 1 | C102: 1080000000
A103: Conveyor System Upgrade | B103: 2 | C103: 2660000000
A104: Technical Mismatch | B104: 1 | C104: 1250000000
...

Sheet Insight
A1: 🎯 KEY INSIGHTS — TENDER WIN/LOSS ANALYSIS 2022-2025 (17 STRATEGIC FINDINGS)
A3: 1. INDUSTRY FOCUS — SUGAR DOMINANCE
A4: Sugar industry adalah segmen terkuat saya — win rate ~75% dengan ~50% dari total tender volume
A5: ACTION: Double down marketing budget di sugar belt Indonesia (Lampung, East Java).
A7: 2. POWER GENERATION = HIDDEN CHAMPION
A8: Win rate tertinggi (75%) meskipun volume hanya 23%. Efisiensi per tender lebih tinggi dari sugar!
A9: ACTION: Tingkatkan exposure di power generation — ROI per tender lebih bagus.
A11: 3. PULP & PAPER = PROBLEM AREA
A12: Win rate terendah (54%) — hampir flip coin. Ada systemic issue (pricing/specs/competitor).
A13: ACTION: Audit losses di pulp & paper — identifikasi root cause untuk improvement.
A15: 4. PROCESS MACHINERY = ⭐ STAR CATEGORY
A16: Win Rate ~75% dengan avg value Rp 2 miliar+. High win × high value = sweet spot.
... A57: 12. PERFORMANCE TREND — STRONG IMPROVING 📈
A58: ="Win rate 2022 = "&TEXT(AVERAGEIFS(Pivot_Analyses!I113:I128,Pivot_Analyses!G113:G128,"Q*-2022"),"0,0%")&" → 2025 = "&TEXT(AVERAGEIFS(Pivot_Analyses!I113:I128,Pivot_Analyses!G113:G128,"Q*-2025"),"0,0%")&", peningkatan "&TEXT(Calculation!B21,"0,0%")&" 4 tahun (rata-rata ~3,3% per tahun)" -> Win rate 2022 = 63,1% → 2025 = 76,2%, peningkatan 13,1% 4 tahun (rata-rata ~3,3% per tahun)
A59: Pattern: Skill saya MENINGKAT seiring waktu — 4+ tahun pengalaman terbukti memberikan competitive edge di tender selection & proposal quality.
A60: ACTION: Pertahankan momentum dokumentasikan "winning patterns" dari recent successes untuk replikasi di tender Q1-Q2 2026.
A62: 13. PEAK PERFORMANCE — Q3-2023 = BENCHMARK YEAR 🏆
A63: ="Quarter terbaik: "&Calculation!B25&" dengan win rate "&TEXT(Calculation!B26,"0,0%")&" (peak performance lifetime). Quarter terendah : "&Calculation!B27&" dengan "&TEXT(Calculation!B28,"0,0%")&" (starting baseline)." -> Quarter terbaik: Q3-2023 dengan win rate 85,7% (peak performance lifetime). Quarter terendah : Q2-2022 dengan 57,1% (starting baseline).
A64: Pattern: Q3-2023 adalah peak point — investigate APA yang berbeda di periode ini (tender type, klien, pricing strategy?) untuk replikasi.
A65: ACTION: Reverse-engineer Q3-2023 wins — identify common factor (industry mix? pricing? client size?) yang membuat 85.7% achievable.
A67: 14. VOLUME TREND — STRATEGIC SELECTIVITY 🎯
A68: Total tender 2022 = 27 → 2025 = 25, perubahan -2 tender (slight decrease).
A69: TAPI win rate naik dari 63.1% → 76.2% (+13.1%). Saya BUKAN spray-and-pray — saya selektif dengan tender.
A70: Implikasi: Quality over quantity mindset terbukti efektif — fokus pada tender berpotensi tinggi menghasilkan ROI lebih baik dari ikut semua tender.
A71: ACTION: Pertahankan strategi selektivitas — kembangkan "tender qualification framework" untuk filter sebelum invest waktu.
A73: 15. REGIONAL SPECIALIZATION — INDUSTRY-GEOGRAPHIC MAP 🗺️
A74: Pattern: 6 dari 8 region punya 100% single-industry concentration. Lampung/East Java/Central Java = pure Sugar, Riau/East Kalimantan = pure Pulp & Paper, Jakarta/West Java = pure Power Gen.
A75: Sugar Belt (54%): Lampung-17, East Java-14, Central Java-14, South Sumatra-11. Power Belt (23%): Jakarta-9, West Java-8, South Sumatra-7. Pulp Belt (23%): Riau-12, East Kalimantan-12.
A76: Implikasi: Geographic footprint kami mengikuti REAL industrial ecosystem Indonesia — HTI Sumatra/Kaltim untuk pulp, sentra tebu Jawa-Lampung, PLN Jamali untuk power. Ini bukan kebetulan.
A77: ACTION: Stop "spray expansion" — pilih ekspansi berdasarkan industry ekosistem, bukan region. Tiap region baru = industry baru otomatis.
... A89: ACTION: Riau bukan masalah teknis tapi masalah PRICING STRATEGY di market commodity. Renegotiate principal pricing untuk Riau + selective bidding di tender yang clearly price war.

Sheet Dashboard
A1: TENDER ANALYTIC DASHBOARD
A2: B2B Industrial Equipment | 2022 - 2025 | 104 Records | 17 Strategic Insights
A5: 104 TOTAL TENDER | D5: 69% WIN RATE | G5: Rp. 167,6 B TOTAL VALUE | J5: 17 STRATEGIC INSIGHTS | M5: +13.1% 4-YEAR TREND
A32: 💡 KEY STRATEGIC INSIGHTS
A33: 1. SUGAR INDUSTRY DOMINANCE 73% win rate, 54% volume — strategic specialization opportunity
A34: 2. MATERIAL HANDLING HIDDEN PROBLEM 43.8% win rate, Rp 10.6B lost — needs pricing review
A35: 3. PRICING IS THE #1 BATTLEGROUND 78% of all losses driven by price competitiveness — Rp 49.8B opportunity gap
A36: 4. WEST JAVA: THE HIDDEN WINNER 88% win rate despite smallest volume (8 tenders) — replicate the focused-account playbook
A37: 5. PERFORMANCE TREND: +13.1% IMPROVEMENT (2022→2025) Strategic selectivity validated — quality over quantity drives sustainable growth
A38: Built by Abdurrahman Rahyang | rahyangabdurrahman@gmail.com | linkedin.com/in/abdurrahman-rahyang
